Workbook

Sheet Tasks
A1: Task ID | B1: Source ID | C1: Release | D1: Priority | E1: Category | F1: Area | G1: Task title | H1: Detailed instructions | I1: Acceptance criteria | J1: Files / modules | K1: Dependencies | L1: Estimate | M1: Test instructions | N1: Done? | O1: Notes | P1: Location | Q1: Risk | R1: Recommendation | S1: Est. AI cost (USD)
A2: T-0001 | B2: BUG-001 | C2: v0.2 | D2: P0 | E2: Bug | F2: Auth | G2: Any user can self-assign a company and read its AI key | H2: The users update rule only pins status, role and email; companyId is free. A regular approved user can call updateDoc(users/{me}, {companyId: X}) from the browser console, after which the companies read rule (isMyCompany) lets them read companies/X including anthropicApiKey and then spend that company's budget. Superadmin-only assignment in Settings is UI-only. Reproduction: Sign in as a normal approved user. In DevTools run updateDoc on users/<uid> with {companyId:'<any company id>'} (ids are visible to superadmins; brute-force is not needed if the user was ever in a company). Then getDoc(companies/<id>) returns the API key. Root cause: Self-update rule enumerates immutable fields instead of allowing only displayName/photoURL; companyId is a privilege field written by the same document path. Fix: In the users update rule add request.resource.data.get('companyId','') == resource.data.get('companyId','') to the self branch (or use diff().affectedKeys().hasOnly(['displayName','photoURL'])). Deploy with npm run deploy:rules. Longer term move the key server-side (see the AI-proxy finding). Where to see it: Settings → User Management (Company dropdown) / any page with DevTools Risk of applying: High — Rules change affects every profile write; superadmin assignment path must keep working. No emulator tests exist today. Recommendation: On-Hold. Files: firestore.rules:340-348 · firestore.rules:301-309 · src/services/firebase.js:271-275 | I2: 1. Given an approved non-superadmin user 2. When they write companyId on their own users document 3. Then Firestore rejects the write with permission-denied and no company document becomes readable | J2: firestore.rules:340-348 · firestore.rules:301-309 · src/services/firebase.js:271-275 | L2: S | M2: Add a Firestore emulator rules test (firebase emulators:exec) that asserts the self-update with companyId is denied and superadmin update is allowed; manually verify with the console steps above after deploying rules. Run: npm test | P2: Settings → User Management (Company dropdown) / any page with DevTools | Q2: High | R2: Proceed | S2: 0
A3: T-0002 | B3: BUG-002 | C3: v0.2 | D3: P0 | E3: Security | F3: Auth | G3: Invite links let any signed-in user become project admin — API/data layer | H3: invites create only requires userId == auth.uid, so anyone can create an invite for ANY projectId with role 'admin' and immediately claim it; isClaimingInvite then grants the ACL. Worse, invites are readable by every authenticated user (allow read: if request.auth != null), so all live invite ids (the 'secret' URL) and projectIds are enumerable. presence is also world-readable and leaks taskIds and names across workspaces. Reproduction: As any approved user, getDocs(collection('invites')) lists every invite. Or addDoc(invites,{userId:me,projectId:<target>,role:'admin',revoked:false,claims:[]}) then call claimInvite(id) → you are admin of the target project and can read/edit its tasks. Root cause: Invite creation is not gated on project admin/owner rights, invite reads are not restricted to the creator or exact-id lookups, and claim validation trusts the invite doc. Fix: Rules: allow create only if hasProjectRole(projectId,'admin') || isOwner(project) || isWorkspaceAdmin(project.workspaceId); allow read only to the creator (list) — claiming should fetch by exact doc id (get) which works without list permission; restrict presence read to workspace members or drop cross-workspace fields. Where to see it: Projects → project editor → Sharing → Generate invite link Risk of applying: High — Changes rule semantics for invites and presence; getInvite currently uses a query on __name__ which needs list permission — switch it to getDoc. Recommendation: On-Hold. Scope of this row: server-side changes only (routes, validation, database, spec). Leave the UI for the next row. | I3: 1. Given a user who is not an admin of project P 2. When they create an invite for P 3. Then the write is denied 4. Given a valid invite id 5. When the recipient opens #/invite/<id> 6. Then claim still succeeds | J3: firestore.rules:188-198 · firestore.rules:169-186 · firestore.rules:272-278 · src/services/firebase.js:1984-2062 | L3: M | M3: Emulator rules tests for: non-admin create denied; admin create allowed; list invites denied for non-creator; get-by-id allowed. Manual: generate link in Projects → Share, open in incognito, accept. Run: npm test | P3: Projects → project editor → Sharing → Generate invite link | Q3: High | R3: Proceed | S3: 0
A4: T-0003 | B4: BUG-002 | C4: v0.2 | D4: P0 | E4: Security | F4: Auth | G4: Invite links let any signed-in user become project admin — UI | H4: invites create only requires userId == auth.uid, so anyone can create an invite for ANY projectId with role 'admin' and immediately claim it; isClaimingInvite then grants the ACL. Worse, invites are readable by every authenticated user (allow read: if request.auth != null), so all live invite ids (the 'secret' URL) and projectIds are enumerable. presence is also world-readable and leaks taskIds and names across workspaces. Reproduction: As any approved user, getDocs(collection('invites')) lists every invite. Or addDoc(invites,{userId:me,projectId:<target>,role:'admin',revoked:false,claims:[]}) then call claimInvite(id) → you are admin of the target project and can read/edit its tasks. Root cause: Invite creation is not gated on project admin/owner rights, invite reads are not restricted to the creator or exact-id lookups, and claim validation trusts the invite doc. Fix: Rules: allow create only if hasProjectRole(projectId,'admin') || isOwner(project) || isWorkspaceAdmin(project.workspaceId); allow read only to the creator (list) — claiming should fetch by exact doc id (get) which works without list permission; restrict presence read to workspace members or drop cross-workspace fields. Where to see it: Projects → project editor → Sharing → Generate invite link Risk of applying: High — Changes rule semantics for invites and presence; getInvite currently uses a query on __name__ which needs list permission — switch it to getDoc. Recommendation: On-Hold. Scope of this row: client-side changes (pages, components, styles) that use the API from T-0002. Plain-language inputs only. | I4: 1. Given a user who is not an admin of project P 2. When they create an invite for P 3. Then the write is denied 4. Given a valid invite id 5. When the recipient opens #/invite/<id> 6. Then claim still succeeds | J4: firestore.rules:188-198 · firestore.rules:169-186 · firestore.rules:272-278 · src/services/firebase.js:1984-2062 | K4: T-0002 | L4: M | M4: Emulator rules tests for: non-admin create denied; admin create allowed; list invites denied for non-creator; get-by-id allowed. Manual: generate link in Projects → Share, open in incognito, accept. Run: npm test | P4: Projects → project editor → Sharing → Generate invite link | Q4: High | R4: Proceed | S4: 0
A5: T-0004 | B5: BUG-002 | C5: v0.2 | D5: P0 | E5: Test | F5: Auth | G5: Invite links let any signed-in user become project admin — tests & docs | H5: Add automated tests covering BUG-002 (API and, where possible, UI), update README.md/Implementation_plan.md status, append CHANGELOG.md. | I5: 1. Given a user who is not an admin of project P 2. When they create an invite for P 3. Then the write is denied 4. Given a valid invite id 5. When the recipient opens #/invite/<id> 6. Then claim still succeeds | J5: server/src/app.test.ts · README.md · Implementation_plan.md · CHANGELOG.md | K5: T-0002, T-0003 | L5: S | M5: npm test passes; docs mention the feature. | P5: Projects → project editor → Sharing → Generate invite link | Q5: Low | R5: Proceed | S5: 0
A6: T-0005 | B6: BUG-003 | C6: v0.2 | D6: P0 | E6: Bug | F6: Auth | G6: Approval gate is client-side only; pending users can write data | H6: App.jsx routes pending/rejected users to PendingApprovalView, but firestore.rules never checks users/{uid}.status for workspaces, projects, tasks, activities etc. A rejected user can still create workspaces and documents through the SDK, and can claim invites. Reproduction: Sign in with an unapproved Google account, then from DevTools call addWorkspace(uid,{name:'x'}) — it succeeds. Root cause: No isApprovedUser() helper in rules. Fix: Add function isApproved(){ return exists(users/uid) && get(users/uid).data.status=='approved'; } and AND it into every create/update/delete rule (and reads except users/{self}). Where to see it: Waiting for approval screen (whole app) Risk of applying: High — Adds a document read to every rule evaluation (cost); superadmin bootstrap path must stay allowed. Recommendation: On-Hold. Files: src/App.jsx:105-113 · firestore.rules:95-112 · firestore.rules:130-148 | I6: 1. Given a user whose profile status is pending or rejected 2. When they attempt any Firestore write outside users/{self} 3. Then it is denied | J6: src/App.jsx:105-113 · firestore.rules:95-112 · firestore.rules:130-148 | L6: M | M6: Emulator rules tests with a pending user fixture; manual check via DevTools as above. Run: npm test | P6: Waiting for approval screen (whole app) | Q6: High | R6: Proceed | S6: 0
A7: T-0006 | B7: BUG-004 | C7: v0.2 | D7: P1 | E7: Bug | F7: DB | G7: Next recurring task is created without workspaceId | H7: spawnNextRecurrence writes the new task without workspaceId (and without assignedTo/links/customValues). The create rule then only passes via the projectId branch, and even when it passes the task is invisible to subscribeToTasks(workspaceId), so the 'next instance' silently never appears on the Board. Reproduction: Create a task with Recurring = weekly, drag it to Done. Look for the next instance on the Board/Calendar: it is missing (or console shows permission-denied). Root cause: Copy of the task payload predates the workspace model; addTask enforces workspaceId but spawnNextRecurrence bypasses addTask. Fix: Reuse addTask(task.userId,{...task fields, workspaceId: task.workspaceId, recurrenceParentId, plan: next}) so all v9+ fields are inherited; add a unit test around nextRecurrenceDates and a spawn test with a mocked addDoc. Where to see it: Kanban → task card → drag to Done Risk of applying: High — Creates stored documents; existing orphaned instances need a one-off backfill of workspaceId. Recommendation: On-Hold. Files: src/services/firebase.js:1060-1111 · src/services/firebase.js:1129-1148 | I7: 1. Given a weekly recurring task in workspace W 2. When it is marked done 3. Then a new todo task with the same workspaceId and shifted dates appears on the Board of W | J7: src/services/firebase.js:1060-1111 · src/services/firebase.js:1129-1148 | L7: S | M7: Mark a recurring task done; confirm the new card appears with 🔁 badge and correct dates; check Firestore doc has workspaceId. Run: npm test | P7: Kanban → task card → drag to Done | Q7: High | R7: Proceed | S7: 0
A8: T-0007 | B8: IMP-002 | C8: v0.2 | D8: P1 | E8: Security | F8: Infra | G8: Bridge lets web pages set the executable it spawns | H8: POST /ai/settings accepts cliPath and the bridge spawns that path for every question. Any page on an allow-listed origin (including the production site) can point the bridge at an arbitrary local binary with attacker-controlled argv, turning an XSS or compromised deploy into local code execution on the operator's Mac. Reproduction: From the production site console: fetch('http://127.0.0.1:4319/ai/settings',{method:'POST',headers:{'content-type':'application/json'},body:JSON.stringify({cliPath:'/usr/bin/say'})}) then trigger any AI call. Root cause: Settings endpoint exposes an unrestricted path field without an auth token. Fix: Drop cliPath from the HTTP-settable keys (env/config-file only), validate cliModel against a whitelist, and require a per-session token that the UI reads from the bridge console output or a local file. Where to see it: Settings → AI brain (superadmin) / bridge Risk of applying: High — Untested path; changes bridge contract used by Settings save. Recommendation: On-Hold. Files: bridge/server.mjs:254-258 · bridge/ai.mjs:53-69 · bridge/ai.mjs:77-79 | I8: 1. Given the bridge is running 2. When a page posts cliPath to /ai/settings 3. Then the response ignores it and the CLI path stays unchanged | J8: bridge/server.mjs:254-258 · bridge/ai.mjs:53-69 · bridge/ai.mjs:77-79 | L8: S | M8: Add a node --test case for setAiSettings ignoring cliPath from HTTP; curl the endpoint and read GET /ai/settings. Run: npm test | P8: Settings → AI brain (superadmin) / bridge | Q8: High | R8: Proceed | S8: 0
A9: T-0008 | B9: IMP-004 | C9: v0.2 | D9: P1 | E9: Improvement | F9: UI | G9: No error boundary; render errors blank the app | H9: main.jsx renders App with no React error boundary. A thrown render error (e.g. a task with unexpected data shape in a card) leaves the user with a white page and no recovery. Reproduction: Temporarily throw inside CardBody; the entire app disappears. Root cause: Missing boundary component. Fix: Add an ErrorBoundary around AppShell and around each Suspense view with a friendly message and Reload button; log to console. Where to see it: All pages Risk of applying: Low — Additive component. Recommendation: Proceed. Files: src/main.jsx:7-16 · src/App.jsx:62-116 | I9: 1. Given one view throws 2. When it renders 3. Then the sidebar stays usable and the view shows an error card with Retry | J9: src/main.jsx:7-16 · src/App.jsx:62-116 | L9: S | M9: Inject a throw in a lazy view and verify the fallback. Run: npm test | P9: All pages | Q9: Low | R9: Proceed | S9: 0
A10: T-0009 | B10: IMP-005 | C10: v0.2 | D10: P1 | E10: Improvement | F10: Test | G10: Tests cover only bridge parsing and due-alert rules — API/data layer | H10: npm test runs bridge/*.test.mjs and src/**/*.test.mjs; untested: recurrence date math, nlpQuickAdd parser, askAi digest/search/action resolution (1,500 lines), CSV parser, and all Firestore security rules. Most of the bugs in this audit sit in untested code. Reproduction: Run npm test: 3 suites only. Root cause: Pure logic lives inside firebase.js and components, hard to import in node. Fix: Extract recurrence and csv parsing into src/services/*.js pure modules with node --test files; add firebase emulator rules tests under tests/rules with a npm run test:rules script. Where to see it: Developer workflow Risk of applying: Low — Refactor moves pure functions; behaviour unchanged. Recommendation: Proceed. Scope of this row: server-side changes only (routes, validation, database, spec). Leave the UI for the next row. | I10: 1. Given npm test 2. When it runs 3. Then recurrence, quick-add parsing, askAi search and rules suites execute and pass | J10: package.json:9 · src/services/firebase.js:1018-1058 · src/services/nlpQuickAdd.js · src/services/askAi.js · src/components/CsvImporter.jsx:11-34 | L10: M | M10: CI: npm test and firebase emulators:exec 'npm run test:rules'. Run: npm test | P10: Developer workflow | Q10: Low | R10: Proceed | S10: 0
A11: T-0010 | B11: IMP-005 | C11: v0.2 | D11: P1 | E11: Improvement | F11: Test | G11: Tests cover only bridge parsing and due-alert rules — UI | H11: npm test runs bridge/*.test.mjs and src/**/*.test.mjs; untested: recurrence date math, nlpQuickAdd parser, askAi digest/search/action resolution (1,500 lines), CSV parser, and all Firestore security rules. Most of the bugs in this audit sit in untested code. Reproduction: Run npm test: 3 suites only. Root cause: Pure logic lives inside firebase.js and components, hard to import in node. Fix: Extract recurrence and csv parsing into src/services/*.js pure modules with node --test files; add firebase emulator rules tests under tests/rules with a npm run test:rules script. Where to see it: Developer workflow Risk of applying: Low — Refactor moves pure functions; behaviour unchanged. Recommendation: Proceed. Scope of this row: client-side changes (pages, components, styles) that use the API from T-0009. Plain-language inputs only. | I11: 1. Given npm test 2. When it runs 3. Then recurrence, quick-add parsing, askAi search and rules suites execute and pass | J11: package.json:9 · src/services/firebase.js:1018-1058 · src/services/nlpQuickAdd.js · src/services/askAi.js · src/components/CsvImporter.jsx:11-34 | K11: T-0009 | L11: M | M11: CI: npm test and firebase emulators:exec 'npm run test:rules'. Run: npm test | P11: Developer workflow | Q11: Low | R11: Proceed | S11: 0
A12: T-0011 | B12: IMP-005 | C12: v0.2 | D12: P1 | E12: Test | F12: Test | G12: Tests cover only bridge parsing and due-alert rules — tests & docs | H12: Add automated tests covering IMP-005 (API and, where possible, UI), update README.md/Implementation_plan.md status, append CHANGELOG.md. | I12: 1. Given npm test 2. When it runs 3. Then recurrence, quick-add parsing, askAi search and rules suites execute and pass | J12: server/src/app.test.ts · README.md · Implementation_plan.md · CHANGELOG.md | K12: T-0009, T-0010 | L12: S | M12: npm test passes; docs mention the feature. | P12: Developer workflow | Q12: Low | R12: Proceed | S12: 0
A13: T-0012 | B13: BUG-005 | C13: v0.2 | D13: P2 | E13: Bug | F13: UI | G13: Default project setting is never applied to quick-add | H13: Settings → Defaults offers 'Default project for quick-add' and stores settings.defaultProject, but TaskForm never reads useSettings; it always preselects projects[0]. Dead control. Reproduction: Set a default project in Settings, go to Kanban with All projects: the quick-add dropdown shows the first project instead. Root cause: Setting was added without wiring the consumer. Fix: In TaskForm, read settings.defaultProject and prefer it (if it exists in projects) before projects[0]. Where to see it: Settings → Defaults; Kanban → quick-add row Risk of applying: Low — Single component change. Recommendation: Proceed. Files: src/components/SettingsView.jsx:355-366 · src/components/TaskForm.jsx:46-54 · src/hooks/useSettings.js:11 | I13: 1. Given defaultProject is set to P 2. When the Board quick-add mounts with All projects 3. Then P is preselected | J13: src/components/SettingsView.jsx:355-366 · src/components/TaskForm.jsx:46-54 · src/hooks/useSettings.js:11 | L13: S | M13: Set default, reload Kanban, check dropdown value. Run: npm test | P13: Settings → Defaults; Kanban → quick-add row | Q13: Low | R13: Proceed | S13: 0
A14: T-0013 | B14: BUG-006 | C14: v0.2 | D14: P2 | E14: Bug | F14: UI | G14: 'Shared' badge can never render | H14: AppShell and ProjectsView render a Shared badge when p._shared is true, but useProjects never sets _shared when merging shared projects. Reproduction: Share a project with a user in another workspace; no Shared badge appears anywhere. Root cause: Flag documented in a comment but not implemented. Fix: In the merge loop set map.set(p.id,{...p,_shared:true}) for shared-only projects. Where to see it: Projects page; topbar project picker Risk of applying: Low — Pure client change. Recommendation: Proceed. Files: src/hooks/useTasks.js:89-109 · src/components/AppShell.jsx:682 · src/components/ProjectsView.jsx:134 | I14: 1. Given a project reached only through project membership 2. When it is listed in the picker or Projects page 3. Then a Shared badge shows | J14: src/hooks/useTasks.js:89-109 · src/components/AppShell.jsx:682 · src/components/ProjectsView.jsx:134 | L14: S | M14: Accept an invite from another workspace, open Projects. Run: npm test | P14: Projects page; topbar project picker | Q14: Low | R14: Proceed | S14: 0
A15: T-0014 | B15: BUG-007 | C15: v0.2 | D15: P2 | E15: Bug | F15: UI | G15: Export file dates use UTC, not the user's day — API/data layer | H15: CSV and JSON exports name files with new Date().toISOString().slice(0,10) (UTC). In Asia/Manila, exports made before 08:00 get yesterday's date, breaking the date-stamp requirement and the WBSView export which uses todayLocal(). Reproduction: At 07:00 local, click Export all CSV: filename shows the previous date. Root cause: Mixed date helpers. Fix: Use todayLocal() from services/firebase.js in every download name, and centralise in one downloadFile(name, blob) helper. Where to see it: Activity Log → Export; Projects → Log → Download CSV; Settings → Export JSON; WBS modal Risk of applying: Low — Four files, naming only. Recommendation: Proceed. Scope of this row: server-side changes only (routes, validation, database, spec). Leave the UI for the next row. | I15: 1. Given local time 07:00 on 2026-09-12 2. When any export runs 3. Then the filename ends with -2026-09-12.<ext> | J15: src/components/TableView.jsx:307 · src/components/ProjectsView.jsx:371 · src/components/SettingsView.jsx:807 · src/components/WbsModal.jsx:85 | L15: S | M15: Change system clock or mock Date; run each export. Run: npm test | P15: Activity Log → Export; Projects → Log → Download CSV; Settings → Export JSON; WBS modal | Q15: Low | R15: Proceed | S15: 0
A16: T-0015 | B16: BUG-007 | C16: v0.2 | D16: P2 | E16: Bug | F16: UI | G16: Export file dates use UTC, not the user's day — UI | H16: CSV and JSON exports name files with new Date().toISOString().slice(0,10) (UTC). In Asia/Manila, exports made before 08:00 get yesterday's date, breaking the date-stamp requirement and the WBSView export which uses todayLocal(). Reproduction: At 07:00 local, click Export all CSV: filename shows the previous date. Root cause: Mixed date helpers. Fix: Use todayLocal() from services/firebase.js in every download name, and centralise in one downloadFile(name, blob) helper. Where to see it: Activity Log → Export; Projects → Log → Download CSV; Settings → Export JSON; WBS modal Risk of applying: Low — Four files, naming only. Recommendation: Proceed. Scope of this row: client-side changes (pages, components, styles) that use the API from T-0014. Plain-language inputs only. | I16: 1. Given local time 07:00 on 2026-09-12 2. When any export runs 3. Then the filename ends with -2026-09-12.<ext> | J16: src/components/TableView.jsx:307 · src/components/ProjectsView.jsx:371 · src/components/SettingsView.jsx:807 · src/components/WbsModal.jsx:85 | K16: T-0014 | L16: S | M16: Change system clock or mock Date; run each export. Run: npm test | P16: Activity Log → Export; Projects → Log → Download CSV; Settings → Export JSON; WBS modal | Q16: Low | R16: Proceed | S16: 0
A17: T-0016 | B17: BUG-007 | C17: v0.2 | D17: P2 | E17: Test | F17: UI | G17: Export file dates use UTC, not the user's day — tests & docs | H17: Add automated tests covering BUG-007 (API and, where possible, UI), update README.md/Implementation_plan.md status, append CHANGELOG.md. | I17: 1. Given local time 07:00 on 2026-09-12 2. When any export runs 3. Then the filename ends with -2026-09-12.<ext> | J17: server/src/app.test.ts · README.md · Implementation_plan.md · CHANGELOG.md | K17: T-0014, T-0015 | L17: S | M17: npm test passes; docs mention the feature. | P17: Activity Log → Export; Projects → Log → Download CSV; Settings → Export JSON; WBS modal | Q17: Low | R17: Proceed | S17: 0
A18: T-0017 | B18: BUG-008 | C18: v0.2 | D18: P2 | E18: Bug | F18: AI | G18: Bridge API mode is labelled as subscription billing — API/data layer | H18: detectProvider maps a bridge whose aiMode is 'api' to 'claude-code', so the AI brain panel says 'Thinking on your Claude subscription — no API billing' while the bridge is actually calling the Anthropic API per token. Separately, MyCompanyAiStatus tells users without a company that AI is unavailable, but isAiAllowedForUser() returns true for them and the local bridge works. Reproduction: Run the bridge with ANTHROPIC_API_KEY and no claude CLI; open Settings → AI brain. Root cause: Provider enum conflates transport (bridge) with billing model. Fix: Introduce provider 'bridge-api' (or carry health.aiMode through) and label accordingly; make the non-admin card read useAiStatus() instead of companyId presence. Where to see it: Settings → AI brain / AI access Risk of applying: Low — Label logic only. Recommendation: Proceed. Scope of this row: server-side changes only (routes, validation, database, spec). Leave the UI for the next row. | I18: 1. Given the bridge is in api mode 2. When Settings loads 3. Then the headline says the Anthropic API is billed per token | J18: src/services/ai.js:163-171 · src/components/SettingsView.jsx:534-542 · src/components/SettingsView.jsx:1603-1614 · src/services/aiCredentials.js:66-69 | L18: S | M18: Start bridge with only an API key; check badge and headline. Run: npm test | P18: Settings → AI brain / AI access | Q18: Low | R18: Proceed | S18: 0
A19: T-0018 | B19: BUG-008 | C19: v0.2 | D19: P2 | E19: Bug | F19: AI | G19: Bridge API mode is labelled as subscription billing — UI | H19: detectProvider maps a bridge whose aiMode is 'api' to 'claude-code', so the AI brain panel says 'Thinking on your Claude subscription — no API billing' while the bridge is actually calling the Anthropic API per token. Separately, MyCompanyAiStatus tells users without a company that AI is unavailable, but isAiAllowedForUser() returns true for them and the local bridge works. Reproduction: Run the bridge with ANTHROPIC_API_KEY and no claude CLI; open Settings → AI brain. Root cause: Provider enum conflates transport (bridge) with billing model. Fix: Introduce provider 'bridge-api' (or carry health.aiMode through) and label accordingly; make the non-admin card read useAiStatus() instead of companyId presence. Where to see it: Settings → AI brain / AI access Risk of applying: Low — Label logic only. Recommendation: Proceed. Scope of this row: client-side changes (pages, components, styles) that use the API from T-0017. Plain-language inputs only. | I19: 1. Given the bridge is in api mode 2. When Settings loads 3. Then the headline says the Anthropic API is billed per token | J19: src/services/ai.js:163-171 · src/components/SettingsView.jsx:534-542 · src/components/SettingsView.jsx:1603-1614 · src/services/aiCredentials.js:66-69 | K19: T-0017 | L19: S | M19: Start bridge with only an API key; check badge and headline. Run: npm test | P19: Settings → AI brain / AI access | Q19: Low | R19: Proceed | S19: 0
A20: T-0019 | B20: BUG-008 | C20: v0.2 | D20: P2 | E20: Test | F20: AI | G20: Bridge API mode is labelled as subscription billing — tests & docs | H20: Add automated tests covering BUG-008 (API and, where possible, UI), update README.md/Implementation_plan.md status, append CHANGELOG.md. | I20: 1. Given the bridge is in api mode 2. When Settings loads 3. Then the headline says the Anthropic API is billed per token | J20: server/src/app.test.ts · README.md · Implementation_plan.md · CHANGELOG.md | K20: T-0017, T-0018 | L20: S | M20: npm test passes; docs mention the feature. | P20: Settings → AI brain / AI access | Q20: Low | R20: Proceed | S20: 0
A21: T-0020 | B21: BUG-011 | C21: v0.2 | D21: P2 | E21: Security | F21: UI | G21: Sidebar user block polls auth every 500 ms | H21: SidebarUserBlock sets a 500 ms interval to compare auth.currentUser instead of subscribing with onAuthStateChanged, causing constant timers and re-renders. Reproduction: Open Performance tab; a timer fires twice per second forever. Root cause: Polling instead of the existing onAuthChange helper. Fix: Use onAuthChange(setUser) in the effect. Where to see it: Sidebar footer Risk of applying: Low — One component. Recommendation: Proceed. Files: src/components/AppShell.jsx:372-381 | I21: 1. Given the app is idle 2. When profiling 3. Then no periodic auth polling timer exists | J21: src/components/AppShell.jsx:372-381 | L21: S | M21: Check that avatar/name still update after sign-in. Run: npm test | P21: Sidebar footer | Q21: Low | R21: Proceed | S21: 0
A22: T-0021 | B22: IMP-006 | C22: v0.2 | D22: P2 | E22: Security | F22: Docs | G22: Docs are stale and there is no root README — API/data layer | H22: No README.md exists at the repo root (CLAUDE.md and the bridge refer to one). docs/BUILD-GUIDE.md and package-scripts.md describe anonymous auth, GitHub Pages and a /task-monitor/ base path that no longer apply; CLAUDE.md lists Google sign-in and multi-user as out of scope though both exist; Settings → Webhooks references a FEATURE_ROADMAP.md that does not exist. Reproduction: Follow BUILD-GUIDE Phase 7 rules or Phase 12 deploy: they conflict with firestore.rules and firebase.json. Root cause: Docs not updated across the workspace/auth/hosting migrations. Fix: Write README.md (install, .env, npm start, bridge, deploy, tests), delete or archive the two docs, refresh CLAUDE.md sections Architecture/Out of scope, remove the roadmap reference. Where to see it: Repository Risk of applying: Low — Docs only. Recommendation: Proceed. Scope of this row: server-side changes only (routes, validation, database, spec). Leave the UI for the next row. | I22: 1. Given a new developer 2. When they follow README.md 3. Then the app runs locally with sign-in in under 15 minutes | J22: docs/BUILD-GUIDE.md · docs/package-scripts.md · CLAUDE.md:234-243 · src/components/SettingsView.jsx:827-831 | L22: S | M22: Dry-run the README on a clean clone. Run: npm test | P22: Repository | Q22: Low | R22: Proceed | S22: 0
A23: T-0022 | B23: IMP-006 | C23: v0.2 | D23: P2 | E23: Security | F23: Docs | G23: Docs are stale and there is no root README — UI | H23: No README.md exists at the repo root (CLAUDE.md and the bridge refer to one). docs/BUILD-GUIDE.md and package-scripts.md describe anonymous auth, GitHub Pages and a /task-monitor/ base path that no longer apply; CLAUDE.md lists Google sign-in and multi-user as out of scope though both exist; Settings → Webhooks references a FEATURE_ROADMAP.md that does not exist. Reproduction: Follow BUILD-GUIDE Phase 7 rules or Phase 12 deploy: they conflict with firestore.rules and firebase.json. Root cause: Docs not updated across the workspace/auth/hosting migrations. Fix: Write README.md (install, .env, npm start, bridge, deploy, tests), delete or archive the two docs, refresh CLAUDE.md sections Architecture/Out of scope, remove the roadmap reference. Where to see it: Repository Risk of applying: Low — Docs only. Recommendation: Proceed. Scope of this row: client-side changes (pages, components, styles) that use the API from T-0021. Plain-language inputs only. | I23: 1. Given a new developer 2. When they follow README.md 3. Then the app runs locally with sign-in in under 15 minutes | J23: docs/BUILD-GUIDE.md · docs/package-scripts.md · CLAUDE.md:234-243 · src/components/SettingsView.jsx:827-831 | K23: T-0021 | L23: S | M23: Dry-run the README on a clean clone. Run: npm test | P23: Repository | Q23: Low | R23: Proceed | S23: 0
A24: T-0023 | B24: IMP-006 | C24: v0.2 | D24: P2 | E24: Test | F24: Docs | G24: Docs are stale and there is no root README — tests & docs | H24: Add automated tests covering IMP-006 (API and, where possible, UI), update README.md/Implementation_plan.md status, append CHANGELOG.md. | I24: 1. Given a new developer 2. When they follow README.md 3. Then the app runs locally with sign-in in under 15 minutes | J24: server/src/app.test.ts · README.md · Implementation_plan.md · CHANGELOG.md | K24: T-0021, T-0022 | L24: S | M24: npm test passes; docs mention the feature. | P24: Repository | Q24: Low | R24: Proceed | S24: 0
A25: T-0024 | B25: IMP-007 | C25: v0.2 | D25: P2 | E25: Improvement | F25: Infra | G25: Local run needs two commands and hidden Firebase config | H25: Running locally requires copying .env.example, then npm run dev AND npm run bridge in separate terminals; without .env the app crashes inside Firebase init with no readable message. The standing requirement is one install and one run command. Reproduction: Fresh clone, npm install, npm run dev → console error auth/invalid-api-key and a blank page. Root cause: No combined start script and no config guard. Fix: Add npm start = concurrently 'vite' 'node bridge/server.mjs' (or a tiny node launcher), and in firebase.js detect a missing VITE_FIREBASE_PROJECT_ID and render a setup screen listing the six variables. Where to see it: Local dev Risk of applying: Low — Adds one devDependency (concurrently) or a script. Recommendation: Proceed. Files: package.json:6-18 · src/services/firebase.js:47-56 · .env.example | I25: 1. Given a clone with no .env 2. When npm start runs 3. Then the browser shows a setup page naming the missing variables instead of a blank page | J25: package.json:6-18 · src/services/firebase.js:47-56 · .env.example | L25: S | M25: Remove .env and start; then add it and confirm normal boot. Run: npm test | P25: Local dev | Q25: Low | R25: Proceed | S25: 0
A26: T-0025 | B26: IMP-009 | C26: v0.2 | D26: P2 | E26: Improvement | F26: UI | G26: Overdue notification memory grows forever | H26: useOverdueScan stores every shown task|date key in localStorage and never prunes; on long-lived devices this list grows unbounded and is scanned on every 5-minute tick. Reproduction: Inspect localStorage task-monitor.notif.shown.v1 after months of use. Root cause: No pruning. Fix: Prune keys whose date is older than 30 days on load (mirroring loadAlertState). Where to see it: Browser notifications Risk of applying: Low — Local storage only. Recommendation: Proceed. Files: src/hooks/useNotifications.js:42-48 · src/hooks/useNotifications.js:95-105 | I26: 1. Given shown keys older than 30 days 2. When the scan runs 3. Then they are dropped | J26: src/hooks/useNotifications.js:42-48 · src/hooks/useNotifications.js:95-105 | L26: S | M26: Seed old keys; run scan; inspect storage. Run: npm test | P26: Browser notifications | Q26: Low | R26: Proceed | S26: 0
A27: T-0026 | B27: POL-003 | C27: v0.2 | D27: P2 | E27: Polish | F27: UI | G27: CLI install instructions shown to every user — API/data layer | H27: KnowledgeSection (rendered for all roles) and the not-available hints show shell commands like pipx install notebooklm-py, npm i -g @anthropic-ai/claude-code and a Bridge URL. The knowledge base and bridge are operator-only concepts; regular users should see plain-language status, not code. Reproduction: Sign in as a non-superadmin, open Settings → Knowledge base. Root cause: Section not gated on role. Fix: Render KnowledgeSection only for superadmins (or when bridgeOk); for others show 'Knowledge base: managed by your admin' with no commands. Where to see it: Settings → Knowledge base Risk of applying: Low — Conditional render. Recommendation: Proceed. Scope of this row: server-side changes only (routes, validation, database, spec). Leave the UI for the next row. | I27: 1. Given a regular user 2. When they open Settings 3. Then no shell commands or URLs are displayed | J27: src/components/SettingsView.jsx:406 · src/components/KnowledgeSection.jsx:42 · bridge/notebooklm.mjs:43-55 · src/services/knowledge.js:19-24 | L27: S | M27: Check Settings with a user role account. Run: npm test | P27: Settings → Knowledge base | Q27: Low | R27: Proceed | S27: 0
A28: T-0027 | B28: POL-003 | C28: v0.2 | D28: P2 | E28: Polish | F28: UI | G28: CLI install instructions shown to every user — UI | H28: KnowledgeSection (rendered for all roles) and the not-available hints show shell commands like pipx install notebooklm-py, npm i -g @anthropic-ai/claude-code and a Bridge URL. The knowledge base and bridge are operator-only concepts; regular users should see plain-language status, not code. Reproduction: Sign in as a non-superadmin, open Settings → Knowledge base. Root cause: Section not gated on role. Fix: Render KnowledgeSection only for superadmins (or when bridgeOk); for others show 'Knowledge base: managed by your admin' with no commands. Where to see it: Settings → Knowledge base Risk of applying: Low — Conditional render. Recommendation: Proceed. Scope of this row: client-side changes (pages, components, styles) that use the API from T-0026. Plain-language inputs only. | I28: 1. Given a regular user 2. When they open Settings 3. Then no shell commands or URLs are displayed | J28: src/components/SettingsView.jsx:406 · src/components/KnowledgeSection.jsx:42 · bridge/notebooklm.mjs:43-55 · src/services/knowledge.js:19-24 | K28: T-0026 | L28: S | M28: Check Settings with a user role account. Run: npm test | P28: Settings → Knowledge base | Q28: Low | R28: Proceed | S28: 0
A29: T-0028 | B29: POL-003 | C29: v0.2 | D29: P2 | E29: Test | F29: UI | G29: CLI install instructions shown to every user — tests & docs | H29: Add automated tests covering POL-003 (API and, where possible, UI), update README.md/Implementation_plan.md status, append CHANGELOG.md. | I29: 1. Given a regular user 2. When they open Settings 3. Then no shell commands or URLs are displayed | J29: server/src/app.test.ts · README.md · Implementation_plan.md · CHANGELOG.md | K29: T-0026, T-0027 | L29: S | M29: npm test passes; docs mention the feature. | P29: Settings → Knowledge base | Q29: Low | R29: Proceed | S29: 0
A30: T-0029 | B30: POL-004 | C30: v0.2 | D30: P2 | E30: Security | F30: UI | G30: Stale copy: anonymous session, email notification promise — API/data layer | H30: Settings says 'Anonymous session <uid>' although anonymous auth was removed; PendingApprovalView and LandingView promise 'we'll notify you by email when approved' but no email is ever sent; Settings subtitle says preferences are per-device while the page also manages workspaces, users and companies. Reproduction: Read the texts on those screens. Root cause: Copy not updated after auth changes. Fix: Rewrite to 'Signed in as <email>'; change the approval copy to 'Check back later or ask an admin' or implement an approval email via a Cloud Function trigger on users status change. Where to see it: Settings → Your data; Waiting for approval; Sign in Risk of applying: Low — Copy only. Recommendation: Proceed. Scope of this row: server-side changes only (routes, validation, database, spec). Leave the UI for the next row. | I30: 1. Given the pending screen 2. When read 3. Then it makes no promise the system does not keep | J30: src/components/SettingsView.jsx:384-387 · src/components/PendingApprovalView.jsx:62-65 · src/components/LandingView.jsx:62-65 · src/components/SettingsView.jsx:228 | L30: S | M30: Visual review. Run: npm test | P30: Settings → Your data; Waiting for approval; Sign in | Q30: Low | R30: Proceed | S30: 0
A31: T-0030 | B31: POL-004 | C31: v0.2 | D31: P2 | E31: Security | F31: UI | G31: Stale copy: anonymous session, email notification promise — UI | H31: Settings says 'Anonymous session <uid>' although anonymous auth was removed; PendingApprovalView and LandingView promise 'we'll notify you by email when approved' but no email is ever sent; Settings subtitle says preferences are per-device while the page also manages workspaces, users and companies. Reproduction: Read the texts on those screens. Root cause: Copy not updated after auth changes. Fix: Rewrite to 'Signed in as <email>'; change the approval copy to 'Check back later or ask an admin' or implement an approval email via a Cloud Function trigger on users status change. Where to see it: Settings → Your data; Waiting for approval; Sign in Risk of applying: Low — Copy only. Recommendation: Proceed. Scope of this row: client-side changes (pages, components, styles) that use the API from T-0029. Plain-language inputs only. | I31: 1. Given the pending screen 2. When read 3. Then it makes no promise the system does not keep | J31: src/components/SettingsView.jsx:384-387 · src/components/PendingApprovalView.jsx:62-65 · src/components/LandingView.jsx:62-65 · src/components/SettingsView.jsx:228 | K31: T-0029 | L31: S | M31: Visual review. Run: npm test | P31: Settings → Your data; Waiting for approval; Sign in | Q31: Low | R31: Proceed | S31: 0
A32: T-0031 | B32: POL-004 | C32: v0.2 | D32: P2 | E32: Test | F32: UI | G32: Stale copy: anonymous session, email notification promise — tests & docs | H32: Add automated tests covering POL-004 (API and, where possible, UI), update README.md/Implementation_plan.md status, append CHANGELOG.md. | I32: 1. Given the pending screen 2. When read 3. Then it makes no promise the system does not keep | J32: server/src/app.test.ts · README.md · Implementation_plan.md · CHANGELOG.md | K32: T-0029, T-0030 | L32: S | M32: npm test passes; docs mention the feature. | P32: Settings → Your data; Waiting for approval; Sign in | Q32: Low | R32: Proceed | S32: 0
A33: T-0032 | B33: POL-005 | C33: v0.2 | D33: P2 | E33: Polish | F33: Infra | G33: Package version and deploy account hardcoded | H33: package.json version is 0.0.0 while the product is at v0.1; the deploy script hardcodes a personal Gmail account, and the topbar has no version/about indicator for support. Reproduction: npm run deploy on another machine fails on the account flag. Root cause: Scripts written for one operator. Fix: Set version 0.1.0, read the account from an env var (FIREBASE_ACCOUNT) and show the version in Settings → About. Where to see it: Settings → About Risk of applying: Low — Scripts only. Recommendation: Proceed. Files: package.json:5 · package.json:14-17 | I33: 1. Given Settings → About 2. When opened 3. Then it shows v0.2.0 matching package.json | J33: package.json:5 · package.json:14-17 | L33: S | M33: Check about section; run deploy with the env var. Run: npm test | P33: Settings → About | Q33: Low | R33: Proceed | S33: 0
A34: T-0033 | B34: BUG-010 | C34: v0.3 | D34: P1 | E34: Security | F34: UI | G34: Board cards each open their own workspace listeners | H34: AssigneeBadges (rendered per card) calls useWorkspaces(), which registers an auth listener, a workspaces onSnapshot and the migration check for every card; each expanded card's useActivities subscribes to the entire workspace activities collection (up to 500 docs) and filters client-side. With 200 cards this means hundreds of listeners and repeated sorting on each snapshot. Reproduction: Open Kanban with 150+ tasks and watch React profiler / Firestore listener count. Root cause: Hooks are used as data sources inside list items; no shared store. Fix: Lift workspace/memberProfiles into a context provided once by AppShell; pass memberProfiles down to cards; make useActivities(taskId) derive from the single useAllActivities subscription. Where to see it: Kanban Risk of applying: Medium — Touches shared hooks used by many views. Recommendation: Proceed. Files: src/components/Board.jsx:638-643 · src/hooks/useWorkspace.js:64-110 · src/hooks/useTasks.js:209-233 | I34: 1. Given 200 tasks on the Board 2. When the view renders 3. Then only one workspaces listener and one activities listener exist | J34: src/components/Board.jsx:638-643 · src/hooks/useWorkspace.js:64-110 · src/hooks/useTasks.js:209-233 | L34: M | M34: Count onSnapshot registrations via a debug counter in firebase.js; profile render time before/after. Run: npm test | P34: Kanban | Q34: Medium | R34: Proceed | S34: 0
A35: T-0034 | B35: IMP-001 | C35: v0.3 | D35: P1 | E35: Improvement | F35: AI | G35: Company Anthropic key is shipped to every member's browser — API/data layer | H35: AI calls in 'api' mode run directly from the browser with the company key and the anthropic-dangerous-direct-browser-access header. Any member can read the key from Network tab or the company doc and use it outside the app; budgets cannot be enforced. Reproduction: As a company member open DevTools → Network while pressing Plan my day; the x-api-key header is visible. Root cause: No backend; key distributed via Firestore to clients. Fix: Add a Cloud Function (or Firebase callable) proxy that holds the key server-side, checks the caller's users doc (approved + companyId + aiEnabled) and forwards to Anthropic; client calls the function instead of api.anthropic.com. Keep the local bridge path for the operator. Where to see it: Settings → AI access / any ✨ button Risk of applying: High — Introduces a backend dependency and billing; rules for companies read change. Recommendation: On-Hold. Scope of this row: server-side changes only (routes, validation, database, spec). Leave the UI for the next row. | I35: 1. Given a company member 2. When they use any AI feature 3. Then no API key is present in the browser or Firestore client reads | J35: src/services/ai.js:253-293 · src/services/aiCredentials.js:71-76 · src/hooks/useCompany.js:37-48 | L35: L | M35: After migration, grep the bundle and Network tab for 'x-api-key'; verify AI still works for a member. Run: npm test | P35: Settings → AI access / any ✨ button | Q35: High | R35: Proceed | S35: 0
A36: T-0035 | B36: IMP-001 | C36: v0.3 | D36: P1 | E36: Improvement | F36: AI | G36: Company Anthropic key is shipped to every member's browser — UI | H36: AI calls in 'api' mode run directly from the browser with the company key and the anthropic-dangerous-direct-browser-access header. Any member can read the key from Network tab or the company doc and use it outside the app; budgets cannot be enforced. Reproduction: As a company member open DevTools → Network while pressing Plan my day; the x-api-key header is visible. Root cause: No backend; key distributed via Firestore to clients. Fix: Add a Cloud Function (or Firebase callable) proxy that holds the key server-side, checks the caller's users doc (approved + companyId + aiEnabled) and forwards to Anthropic; client calls the function instead of api.anthropic.com. Keep the local bridge path for the operator. Where to see it: Settings → AI access / any ✨ button Risk of applying: High — Introduces a backend dependency and billing; rules for companies read change. Recommendation: On-Hold. Scope of this row: client-side changes (pages, components, styles) that use the API from T-0034. Plain-language inputs only. | I36: 1. Given a company member 2. When they use any AI feature 3. Then no API key is present in the browser or Firestore client reads | J36: src/services/ai.js:253-293 · src/services/aiCredentials.js:71-76 · src/hooks/useCompany.js:37-48 | K36: T-0034 | L36: L | M36: After migration, grep the bundle and Network tab for 'x-api-key'; verify AI still works for a member. Run: npm test | P36: Settings → AI access / any ✨ button | Q36: High | R36: Proceed | S36: 0
A37: T-0036 | B37: IMP-001 | C37: v0.3 | D37: P1 | E37: Test | F37: AI | G37: Company Anthropic key is shipped to every member's browser — tests & docs | H37: Add automated tests covering IMP-001 (API and, where possible, UI), update README.md/Implementation_plan.md status, append CHANGELOG.md. | I37: 1. Given a company member 2. When they use any AI feature 3. Then no API key is present in the browser or Firestore client reads | J37: server/src/app.test.ts · README.md · Implementation_plan.md · CHANGELOG.md | K37: T-0034, T-0035 | L37: S | M37: npm test passes; docs mention the feature. | P37: Settings → AI access / any ✨ button | Q37: Low | R37: Proceed | S37: 0
A38: T-0037 | B38: IMP-003 | C38: v0.3 | D38: P1 | E38: Improvement | F38: DB | G38: Whole-collection subscriptions will not scale — API/data layer | H38: Every list (tasks, activities, minutes, goals) is fetched with a single equality filter and sorted/filtered in the browser; subscribeToAllActivities reads every activity then slices 500. No firestore.indexes.json exists. Cost and memory grow linearly with workspace history, and Analytics/Review re-read everything on every change. Reproduction: Import 5,000 activities via CSV; open Activity Log and Dashboard and observe read counts and lag. Root cause: Avoiding composite indexes by design; no pagination. Fix: Add firestore.indexes.json (workspaceId+date desc, workspaceId+status, taskId+date), use orderBy/limit with cursor pagination in Table and Work Performed, and keep Dashboard on a 30-day window query. Where to see it: Activity Log; Dashboard; Analytics Risk of applying: Medium — Requires index deploy and changes to shared subscription API. Recommendation: Proceed. Scope of this row: server-side changes only (routes, validation, database, spec). Leave the UI for the next row. | I38: 1. Given a workspace with 10,000 activities 2. When Activity Log opens 3. Then only the first page (e.g. 200 rows) is read and Load more fetches the next | J38: src/services/firebase.js:1129-1148 · src/services/firebase.js:1279-1302 · firebase.json | L38: L | M38: Seed data in the emulator; watch reads in the Firestore usage tab. Run: npm test | P38: Activity Log; Dashboard; Analytics | Q38: Medium | R38: Proceed | S38: 0
A39: T-0038 | B39: IMP-003 | C39: v0.3 | D39: P1 | E39: Improvement | F39: DB | G39: Whole-collection subscriptions will not scale — UI | H39: Every list (tasks, activities, minutes, goals) is fetched with a single equality filter and sorted/filtered in the browser; subscribeToAllActivities reads every activity then slices 500. No firestore.indexes.json exists. Cost and memory grow linearly with workspace history, and Analytics/Review re-read everything on every change. Reproduction: Import 5,000 activities via CSV; open Activity Log and Dashboard and observe read counts and lag. Root cause: Avoiding composite indexes by design; no pagination. Fix: Add firestore.indexes.json (workspaceId+date desc, workspaceId+status, taskId+date), use orderBy/limit with cursor pagination in Table and Work Performed, and keep Dashboard on a 30-day window query. Where to see it: Activity Log; Dashboard; Analytics Risk of applying: Medium — Requires index deploy and changes to shared subscription API. Recommendation: Proceed. Scope of this row: client-side changes (pages, components, styles) that use the API from T-0037. Plain-language inputs only. | I39: 1. Given a workspace with 10,000 activities 2. When Activity Log opens 3. Then only the first page (e.g. 200 rows) is read and Load more fetches the next | J39: src/services/firebase.js:1129-1148 · src/services/firebase.js:1279-1302 · firebase.json | K39: T-0037 | L39: L | M39: Seed data in the emulator; watch reads in the Firestore usage tab. Run: npm test | P39: Activity Log; Dashboard; Analytics | Q39: Medium | R39: Proceed | S39: 0
A40: T-0039 | B40: IMP-003 | C40: v0.3 | D40: P1 | E40: Test | F40: DB | G40: Whole-collection subscriptions will not scale — tests & docs | H40: Add automated tests covering IMP-003 (API and, where possible, UI), update README.md/Implementation_plan.md status, append CHANGELOG.md. | I40: 1. Given a workspace with 10,000 activities 2. When Activity Log opens 3. Then only the first page (e.g. 200 rows) is read and Load more fetches the next | J40: server/src/app.test.ts · README.md · Implementation_plan.md · CHANGELOG.md | K40: T-0037, T-0038 | L40: S | M40: npm test passes; docs mention the feature. | P40: Activity Log; Dashboard; Analytics | Q40: Low | R40: Proceed | S40: 0
...

Sheet Summary
A1: Task Monitor — task sheet summary
A2: Release v0.1 · generated 2026-09-20 by Ideon
A4: Total tasks | B4: =COUNTA(Tasks!$A$2:$A$85)
A5: Done (YES) | B5: =COUNTIF(Tasks!$N$2:$N$85,"YES")
A6: Blocked | B6: =COUNTIF(Tasks!$N$2:$N$85,"BLOCKED")
A7: On-Hold (needs your review) | B7: =COUNTIFS(Tasks!$R$2:$R$85,"On-Hold",Tasks!$N$2:$N$85,"<>YES")
A8: % done | B8: =IF(COUNTA(Tasks!$A$2:$A$85)=0,0,COUNTIF(Tasks!$N$2:$N$85,"YES")/COUNTA(Tasks!$A$2:$A$85))
A9: Total estimated AI cost (USD) | B9: =SUM(Tasks!$S$2:$S$85)
A11: By release | B11: Tasks | C11: Done | D11: % done
A12: v0.2 | B12: =COUNTIF(Tasks!$C$2:$C$85,"v0.2") | C12: =COUNTIFS(Tasks!$C$2:$C$85,"v0.2",Tasks!$N$2:$N$85,"YES") | D12: =IF(COUNTIF(Tasks!$C$2:$C$85,"v0.2")=0,0,COUNTIFS(Tasks!$C$2:$C$85,"v0.2",Tasks!$N$2:$N$85,"YES")/COUNTIF(Tasks!$C$2:$C$85,"v0.2"))
A13: v0.3 | B13: =COUNTIF(Tasks!$C$2:$C$85,"v0.3") | C13: =COUNTIFS(Tasks!$C$2:$C$85,"v0.3",Tasks!$N$2:$N$85,"YES") | D13: =IF(COUNTIF(Tasks!$C$2:$C$85,"v0.3")=0,0,COUNTIFS(Tasks!$C$2:$C$85,"v0.3",Tasks!$N$2:$N$85,"YES")/COUNTIF(Tasks!$C$2:$C$85,"v0.3"))
A14: v0.4 | B14: =COUNTIF(Tasks!$C$2:$C$85,"v0.4") | C14: =COUNTIFS(Tasks!$C$2:$C$85,"v0.4",Tasks!$N$2:$N$85,"YES") | D14: =IF(COUNTIF(Tasks!$C$2:$C$85,"v0.4")=0,0,COUNTIFS(Tasks!$C$2:$C$85,"v0.4",Tasks!$N$2:$N$85,"YES")/COUNTIF(Tasks!$C$2:$C$85,"v0.4"))
A16: By priority | B16: Tasks | C16: Done | D16: % done
A17: P0 | B17: =COUNTIF(Tasks!$D$2:$D$85,"P0") | C17: =COUNTIFS(Tasks!$D$2:$D$85,"P0",Tasks!$N$2:$N$85,"YES") | D17: =IF(COUNTIF(Tasks!$D$2:$D$85,"P0")=0,0,COUNTIFS(Tasks!$D$2:$D$85,"P0",Tasks!$N$2:$N$85,"YES")/COUNTIF(Tasks!$D$2:$D$85,"P0"))
A18: P1 | B18: =COUNTIF(Tasks!$D$2:$D$85,"P1") | C18: =COUNTIFS(Tasks!$D$2:$D$85,"P1",Tasks!$N$2:$N$85,"YES") | D18: =IF(COUNTIF(Tasks!$D$2:$D$85,"P1")=0,0,COUNTIFS(Tasks!$D$2:$D$85,"P1",Tasks!$N$2:$N$85,"YES")/COUNTIF(Tasks!$D$2:$D$85,"P1"))
A19: P2 | B19: =COUNTIF(Tasks!$D$2:$D$85,"P2") | C19: =COUNTIFS(Tasks!$D$2:$D$85,"P2",Tasks!$N$2:$N$85,"YES") | D19: =IF(COUNTIF(Tasks!$D$2:$D$85,"P2")=0,0,COUNTIFS(Tasks!$D$2:$D$85,"P2",Tasks!$N$2:$N$85,"YES")/COUNTIF(Tasks!$D$2:$D$85,"P2"))
A21: By category | B21: Tasks | C21: Done | D21: % done
A22: Bug | B22: =COUNTIF(Tasks!$E$2:$E$85,"Bug") | C22: =COUNTIFS(Tasks!$E$2:$E$85,"Bug",Tasks!$N$2:$N$85,"YES") | D22: =IF(COUNTIF(Tasks!$E$2:$E$85,"Bug")=0,0,COUNTIFS(Tasks!$E$2:$E$85,"Bug",Tasks!$N$2:$N$85,"YES")/COUNTIF(Tasks!$E$2:$E$85,"Bug"))
A23: Improvement | B23: =COUNTIF(Tasks!$E$2:$E$85,"Improvement") | C23: =COUNTIFS(Tasks!$E$2:$E$85,"Improvement",Tasks!$N$2:$N$85,"YES") | D23: =IF(COUNTIF(Tasks!$E$2:$E$85,"Improvement")=0,0,COUNTIFS(Tasks!$E$2:$E$85,"Improvement",Tasks!$N$2:$N$85,"YES")/COUNTIF(Tasks!$E$2:$E$85,"Improvement"))
A24: Missing feature | B24: =COUNTIF(Tasks!$E$2:$E$85,"Missing feature") | C24: =COUNTIFS(Tasks!$E$2:$E$85,"Missing feature",Tasks!$N$2:$N$85,"YES") | D24: =IF(COUNTIF(Tasks!$E$2:$E$85,"Missing feature")=0,0,COUNTIFS(Tasks!$E$2:$E$85,"Missing feature",Tasks!$N$2:$N$85,"YES")/COUNTIF(Tasks!$E$2:$E$85,"Missing feature"))
A25: New feature | B25: =COUNTIF(Tasks!$E$2:$E$85,"New feature") | C25: =COUNTIFS(Tasks!$E$2:$E$85,"New feature",Tasks!$N$2:$N$85,"YES") | D25: =IF(COUNTIF(Tasks!$E$2:$E$85,"New feature")=0,0,COUNTIFS(Tasks!$E$2:$E$85,"New feature",Tasks!$N$2:$N$85,"YES")/COUNTIF(Tasks!$E$2:$E$85,"New feature"))
A26: Polish | B26: =COUNTIF(Tasks!$E$2:$E$85,"Polish") | C26: =COUNTIFS(Tasks!$E$2:$E$85,"Polish",Tasks!$N$2:$N$85,"YES") | D26: =IF(COUNTIF(Tasks!$E$2:$E$85,"Polish")=0,0,COUNTIFS(Tasks!$E$2:$E$85,"Polish",Tasks!$N$2:$N$85,"YES")/COUNTIF(Tasks!$E$2:$E$85,"Polish"))
A27: Security | B27: =COUNTIF(Tasks!$E$2:$E$85,"Security") | C27: =COUNTIFS(Tasks!$E$2:$E$85,"Security",Tasks!$N$2:$N$85,"YES") | D27: =IF(COUNTIF(Tasks!$E$2:$E$85,"Security")=0,0,COUNTIFS(Tasks!$E$2:$E$85,"Security",Tasks!$N$2:$N$85,"YES")/COUNTIF(Tasks!$E$2:$E$85,"Security"))
A28: Test | B28: =COUNTIF(Tasks!$E$2:$E$85,"Test") | C28: =COUNTIFS(Tasks!$E$2:$E$85,"Test",Tasks!$N$2:$N$85,"YES") | D28: =IF(COUNTIF(Tasks!$E$2:$E$85,"Test")=0,0,COUNTIFS(Tasks!$E$2:$E$85,"Test",Tasks!$N$2:$N$85,"YES")/COUNTIF(Tasks!$E$2:$E$85,"Test"))
A30: By area | B30: Tasks | C30: Done | D30: % done
A31: AI | B31: =COUNTIF(Tasks!$F$2:$F$85,"AI") | C31: =COUNTIFS(Tasks!$F$2:$F$85,"AI",Tasks!$N$2:$N$85,"YES") | D31: =IF(COUNTIF(Tasks!$F$2:$F$85,"AI")=0,0,COUNTIFS(Tasks!$F$2:$F$85,"AI",Tasks!$N$2:$N$85,"YES")/COUNTIF(Tasks!$F$2:$F$85,"AI"))
A32: API | B32: =COUNTIF(Tasks!$F$2:$F$85,"API") | C32: =COUNTIFS(Tasks!$F$2:$F$85,"API",Tasks!$N$2:$N$85,"YES") | D32: =IF(COUNTIF(Tasks!$F$2:$F$85,"API")=0,0,COUNTIFS(Tasks!$F$2:$F$85,"API",Tasks!$N$2:$N$85,"YES")/COUNTIF(Tasks!$F$2:$F$85,"API"))
A33: Auth | B33: =COUNTIF(Tasks!$F$2:$F$85,"Auth") | C33: =COUNTIFS(Tasks!$F$2:$F$85,"Auth",Tasks!$N$2:$N$85,"YES") | D33: =IF(COUNTIF(Tasks!$F$2:$F$85,"Auth")=0,0,COUNTIFS(Tasks!$F$2:$F$85,"Auth",Tasks!$N$2:$N$85,"YES")/COUNTIF(Tasks!$F$2:$F$85,"Auth"))
A34: DB | B34: =COUNTIF(Tasks!$F$2:$F$85,"DB") | C34: =COUNTIFS(Tasks!$F$2:$F$85,"DB",Tasks!$N$2:$N$85,"YES") | D34: =IF(COUNTIF(Tasks!$F$2:$F$85,"DB")=0,0,COUNTIFS(Tasks!$F$2:$F$85,"DB",Tasks!$N$2:$N$85,"YES")/COUNTIF(Tasks!$F$2:$F$85,"DB"))
A35: Docs | B35: =COUNTIF(Tasks!$F$2:$F$85,"Docs") | C35: =COUNTIFS(Tasks!$F$2:$F$85,"Docs",Tasks!$N$2:$N$85,"YES") | D35: =IF(COUNTIF(Tasks!$F$2:$F$85,"Docs")=0,0,COUNTIFS(Tasks!$F$2:$F$85,"Docs",Tasks!$N$2:$N$85,"YES")/COUNTIF(Tasks!$F$2:$F$85,"Docs"))
A36: Infra | B36: =COUNTIF(Tasks!$F$2:$F$85,"Infra") | C36: =COUNTIFS(Tasks!$F$2:$F$85,"Infra",Tasks!$N$2:$N$85,"YES") | D36: =IF(COUNTIF(Tasks!$F$2:$F$85,"Infra")=0,0,COUNTIFS(Tasks!$F$2:$F$85,"Infra",Tasks!$N$2:$N$85,"YES")/COUNTIF(Tasks!$F$2:$F$85,"Infra"))
A37: Test | B37: =COUNTIF(Tasks!$F$2:$F$85,"Test") | C37: =COUNTIFS(Tasks!$F$2:$F$85,"Test",Tasks!$N$2:$N$85,"YES") | D37: =IF(COUNTIF(Tasks!$F$2:$F$85,"Test")=0,0,COUNTIFS(Tasks!$F$2:$F$85,"Test",Tasks!$N$2:$N$85,"YES")/COUNTIF(Tasks!$F$2:$F$85,"Test"))
A38: UI | B38: =COUNTIF(Tasks!$F$2:$F$85,"UI") | C38: =COUNTIFS(Tasks!$F$2:$F$85,"UI",Tasks!$N$2:$N$85,"YES") | D38: =IF(COUNTIF(Tasks!$F$2:$F$85,"UI")=0,0,COUNTIFS(Tasks!$F$2:$F$85,"UI",Tasks!$N$2:$N$85,"YES")/COUNTIF(Tasks!$F$2:$F$85,"UI"))
A40: By risk of applying | B40: Tasks | C40: Done | D40: % done
A41: Low | B41: =COUNTIF(Tasks!$Q$2:$Q$85,"Low") | C41: =COUNTIFS(Tasks!$Q$2:$Q$85,"Low",Tasks!$N$2:$N$85,"YES") | D41: =IF(COUNTIF(Tasks!$Q$2:$Q$85,"Low")=0,0,COUNTIFS(Tasks!$Q$2:$Q$85,"Low",Tasks!$N$2:$N$85,"YES")/COUNTIF(Tasks!$Q$2:$Q$85,"Low"))
A42: Medium | B42: =COUNTIF(Tasks!$Q$2:$Q$85,"Medium") | C42: =COUNTIFS(Tasks!$Q$2:$Q$85,"Medium",Tasks!$N$2:$N$85,"YES") | D42: =IF(COUNTIF(Tasks!$Q$2:$Q$85,"Medium")=0,0,COUNTIFS(Tasks!$Q$2:$Q$85,"Medium",Tasks!$N$2:$N$85,"YES")/COUNTIF(Tasks!$Q$2:$Q$85,"Medium"))
A43: High | B43: =COUNTIF(Tasks!$Q$2:$Q$85,"High") | C43: =COUNTIFS(Tasks!$Q$2:$Q$85,"High",Tasks!$N$2:$N$85,"YES") | D43: =IF(COUNTIF(Tasks!$Q$2:$Q$85,"High")=0,0,COUNTIFS(Tasks!$Q$2:$Q$85,"High",Tasks!$N$2:$N$85,"YES")/COUNTIF(Tasks!$Q$2:$Q$85,"High"))
A45: By recommendation | B45: Tasks | C45: Done | D45: % done
A46: Proceed | B46: =COUNTIF(Tasks!$R$2:$R$85,"Proceed") | C46: =COUNTIFS(Tasks!$R$2:$R$85,"Proceed",Tasks!$N$2:$N$85,"YES") | D46: =IF(COUNTIF(Tasks!$R$2:$R$85,"Proceed")=0,0,COUNTIFS(Tasks!$R$2:$R$85,"Proceed",Tasks!$N$2:$N$85,"YES")/COUNTIF(Tasks!$R$2:$R$85,"Proceed"))
A47: On-Hold | B47: =COUNTIF(Tasks!$R$2:$R$85,"On-Hold") | C47: =COUNTIFS(Tasks!$R$2:$R$85,"On-Hold",Tasks!$N$2:$N$85,"YES") | D47: =IF(COUNTIF(Tasks!$R$2:$R$85,"On-Hold")=0,0,COUNTIFS(Tasks!$R$2:$R$85,"On-Hold",Tasks!$N$2:$N$85,"YES")/COUNTIF(Tasks!$R$2:$R$85,"On-Hold"))
